Workbook

Sheet Cómo revisar
A1: Revisión de textos · Acreditaciones de arbolado urbano
A2: Inventario generado de la versión de prueba 0.67 · 812 textos
A4: Cómo revisar
A5: 1. Ve a la hoja «Textos». Filtra por Pantalla, Tipo o Quién lo ve para revisar por partes (por ejemplo, primero todos los avisos).
A6: 2. «Cuándo aparece» dice en qué caso ve la persona ese texto (perfil, estado de la solicitud, respuesta o error).
A7: 3. Si el texto está bien, cambia Estado a «OK». Si no, escribe el texto nuevo en «Tu corrección» y pon «Cambiar».
A8: 4. «Quitar» elimina el texto; «Duda» deja una pregunta en «Comentario».
A9: 5. Sólo edita las columnas amarillas (Tu corrección, Estado, Comentario). Las demás vienen del sistema.
A10: 6. «Observación de Claude» señala textos que contradicen una regla o tienen un pendiente.
A11: 7. Devuélveme el archivo: aplico los cambios en el sitio, el catálogo de la base y los mensajes, corro las pruebas y publico la siguiente versión.
A13: Ejemplo de fila revisada
A14: Texto actual | B14: Llenas tu solicitud y cargas tus documentos en PDF o en foto.
A15: Tu corrección | B15: Llenas tu solicitud y cargas tus documentos en PDF.
A16: Estado | B16: Cambiar
A17: Comentario | B17: Sólo se aceptan PDF.
A19: Avance por pantalla
A20: Pantalla | B20: Textos | C20: Pendientes | D20: OK | E20: Cambiar | F20: Quitar o duda
A21: Todas las pantallas | B21: =COUNTIF(Textos!$B$2:$B$813,A21) | C21: =COUNTIFS(Textos!$B$2:$B$813,A21,Textos!$H$2:$H$813,"Pendiente") | D21: =COUNTIFS(Textos!$B$2:$B$813,A21,Textos!$H$2:$H$813,"OK") | E21: =COUNTIFS(Textos!$B$2:$B$813,A21,Textos!$H$2:$H$813,"Cambiar") | F21: =COUNTIFS(Textos!$B$2:$B$813,A21,Textos!$H$2:$H$813,"Quitar")+COUNTIFS(Textos!$B$2:$B$813,A21,Textos!$H$2:$H$813,"Duda")
A22: Inicio | B22: =COUNTIF(Textos!$B$2:$B$813,A22) | C22: =COUNTIFS(Textos!$B$2:$B$813,A22,Textos!$H$2:$H$813,"Pendiente") | D22: =COUNTIFS(Textos!$B$2:$B$813,A22,Textos!$H$2:$H$813,"OK") | E22: =COUNTIFS(Textos!$B$2:$B$813,A22,Textos!$H$2:$H$813,"Cambiar") | F22: =COUNTIFS(Textos!$B$2:$B$813,A22,Textos!$H$2:$H$813,"Quitar")+COUNTIFS(Textos!$B$2:$B$813,A22,Textos!$H$2:$H$813,"Duda")
A23: Crea tu cuenta | B23: =COUNTIF(Textos!$B$2:$B$813,A23) | C23: =COUNTIFS(Textos!$B$2:$B$813,A23,Textos!$H$2:$H$813,"Pendiente") | D23: =COUNTIFS(Textos!$B$2:$B$813,A23,Textos!$H$2:$H$813,"OK") | E23: =COUNTIFS(Textos!$B$2:$B$813,A23,Textos!$H$2:$H$813,"Cambiar") | F23: =COUNTIFS(Textos!$B$2:$B$813,A23,Textos!$H$2:$H$813,"Quitar")+COUNTIFS(Textos!$B$2:$B$813,A23,Textos!$H$2:$H$813,"Duda")
A24: Entrar | B24: =COUNTIF(Textos!$B$2:$B$813,A24) | C24: =COUNTIFS(Textos!$B$2:$B$813,A24,Textos!$H$2:$H$813,"Pendiente") | D24: =COUNTIFS(Textos!$B$2:$B$813,A24,Textos!$H$2:$H$813,"OK") | E24: =COUNTIFS(Textos!$B$2:$B$813,A24,Textos!$H$2:$H$813,"Cambiar") | F24: =COUNTIFS(Textos!$B$2:$B$813,A24,Textos!$H$2:$H$813,"Quitar")+COUNTIFS(Textos!$B$2:$B$813,A24,Textos!$H$2:$H$813,"Duda")
A25: Pantallas con cuenta | B25: =COUNTIF(Textos!$B$2:$B$813,A25) | C25: =COUNTIFS(Textos!$B$2:$B$813,A25,Textos!$H$2:$H$813,"Pendiente") | D25: =COUNTIFS(Textos!$B$2:$B$813,A25,Textos!$H$2:$H$813,"OK") | E25: =COUNTIFS(Textos!$B$2:$B$813,A25,Textos!$H$2:$H$813,"Cambiar") | F25: =COUNTIFS(Textos!$B$2:$B$813,A25,Textos!$H$2:$H$813,"Quitar")+COUNTIFS(Textos!$B$2:$B$813,A25,Textos!$H$2:$H$813,"Duda")
A26: Mis trámites | B26: =COUNTIF(Textos!$B$2:$B$813,A26) | C26: =COUNTIFS(Textos!$B$2:$B$813,A26,Textos!$H$2:$H$813,"Pendiente") | D26: =COUNTIFS(Textos!$B$2:$B$813,A26,Textos!$H$2:$H$813,"OK") | E26: =COUNTIFS(Textos!$B$2:$B$813,A26,Textos!$H$2:$H$813,"Cambiar") | F26: =COUNTIFS(Textos!$B$2:$B$813,A26,Textos!$H$2:$H$813,"Quitar")+COUNTIFS(Textos!$B$2:$B$813,A26,Textos!$H$2:$H$813,"Duda")
A27: Solicitud | B27: =COUNTIF(Textos!$B$2:$B$813,A27) | C27: =COUNTIFS(Textos!$B$2:$B$813,A27,Textos!$H$2:$H$813,"Pendiente") | D27: =COUNTIFS(Textos!$B$2:$B$813,A27,Textos!$H$2:$H$813,"OK") | E27: =COUNTIFS(Textos!$B$2:$B$813,A27,Textos!$H$2:$H$813,"Cambiar") | F27: =COUNTIFS(Textos!$B$2:$B$813,A27,Textos!$H$2:$H$813,"Quitar")+COUNTIFS(Textos!$B$2:$B$813,A27,Textos!$H$2:$H$813,"Duda")
A28: Mis datos | B28: =COUNTIF(Textos!$B$2:$B$813,A28) | C28: =COUNTIFS(Textos!$B$2:$B$813,A28,Textos!$H$2:$H$813,"Pendiente") | D28: =COUNTIFS(Textos!$B$2:$B$813,A28,Textos!$H$2:$H$813,"OK") | E28: =COUNTIFS(Textos!$B$2:$B$813,A28,Textos!$H$2:$H$813,"Cambiar") | F28: =COUNTIFS(Textos!$B$2:$B$813,A28,Textos!$H$2:$H$813,"Quitar")+COUNTIFS(Textos!$B$2:$B$813,A28,Textos!$H$2:$H$813,"Duda")
A29: Verificar una acreditación | B29: =COUNTIF(Textos!$B$2:$B$813,A29) | C29: =COUNTIFS(Textos!$B$2:$B$813,A29,Textos!$H$2:$H$813,"Pendiente") | D29: =COUNTIFS(Textos!$B$2:$B$813,A29,Textos!$H$2:$H$813,"OK") | E29: =COUNTIFS(Textos!$B$2:$B$813,A29,Textos!$H$2:$H$813,"Cambiar") | F29: =COUNTIFS(Textos!$B$2:$B$813,A29,Textos!$H$2:$H$813,"Quitar")+COUNTIFS(Textos!$B$2:$B$813,A29,Textos!$H$2:$H$813,"Duda")
A30: Mensajes del formulario (estándar) | B30: =COUNTIF(Textos!$B$2:$B$813,A30) | C30: =COUNTIFS(Textos!$B$2:$B$813,A30,Textos!$H$2:$H$813,"Pendiente") | D30: =COUNTIFS(Textos!$B$2:$B$813,A30,Textos!$H$2:$H$813,"OK") | E30: =COUNTIFS(Textos!$B$2:$B$813,A30,Textos!$H$2:$H$813,"Cambiar") | F30: =COUNTIFS(Textos!$B$2:$B$813,A30,Textos!$H$2:$H$813,"Quitar")+COUNTIFS(Textos!$B$2:$B$813,A30,Textos!$H$2:$H$813,"Duda")
A31: Mensajes al guardar o enviar | B31: =COUNTIF(Textos!$B$2:$B$813,A31) | C31: =COUNTIFS(Textos!$B$2:$B$813,A31,Textos!$H$2:$H$813,"Pendiente") | D31: =COUNTIFS(Textos!$B$2:$B$813,A31,Textos!$H$2:$H$813,"OK") | E31: =COUNTIFS(Textos!$B$2:$B$813,A31,Textos!$H$2:$H$813,"Cambiar") | F31: =COUNTIFS(Textos!$B$2:$B$813,A31,Textos!$H$2:$H$813,"Quitar")+COUNTIFS(Textos!$B$2:$B$813,A31,Textos!$H$2:$H$813,"Duda")
A32: Total | B32: =SUM(B21:B31) | C32: =SUM(C21:C31) | D32: =SUM(D21:D31) | E32: =SUM(E21:E31) | F32: =SUM(F21:F31)

Sheet Textos
A1: ID | B1: Pantalla | C1: Sección | D1: Tipo | E1: Cuándo aparece | F1: Texto actual | G1: Tu corrección | H1: Estado | I1: Comentario | J1: Observación de Claude | K1: Quién lo ve | L1: Dónde se cambia
A2: T001 | B2: Todas las pantallas | C2: Cabecera | D2: Título del sistema | E2: Siempre | F2: Acreditaciones de arbolado urbano | H2: Pendiente | K2: Persona solicitante | L2: Todas las páginas
A3: T002 | B3: Todas las pantallas | C3: Pie | D3: Texto | E3: Siempre | F3: Secretaría del Medio Ambiente de la Ciudad de México · Sistema de Información Ambiental. | H3: Pendiente | K3: Persona solicitante | L3: Todas las páginas
A4: T003 | B4: Todas las pantallas | C4: Acceso con teclado | D4: Enlace | E4: Al navegar con teclado | F4: Ir al contenido | H4: Pendiente | K4: Persona solicitante | L4: Todas las páginas
A5: T004 | B5: Todas las pantallas | C5: Pie | D5: Distintivo | E5: Versión de prueba | F5: Versión de prueba 0.N | H5: Pendiente | K5: Persona solicitante | L5: Código del sitio (sitio/app/version-visible.js)
A6: T005 | B6: Inicio | C6: Acreditación de poda y derribo, y de dictaminador técnico | D6: Título | E6: Siempre | F6: Acreditación de poda y derribo, y de dictaminador técnico | H6: Pendiente | K6: Persona solicitante | L6: Página (sitio/index.html)
A7: T006 | B7: Inicio | C7: Acreditación de poda y derribo, y de dictaminador técnico | D7: Introducción | E7: Siempre | F7: Para trabajar en el arbolado urbano de la Ciudad de México necesitas una acreditación vigente de la Secretaría. Aquí la solicitas por primera vez o la renuevas, y das seguimiento a tu trámite. | H7: Pendiente | K7: Persona solicitante | L7: Página (sitio/index.html)
A8: T007 | B8: Inicio | C8: Acreditación de poda y derribo, y de dictaminador técnico | D8: Texto | E8: Siempre | F8: Crea tu cuenta La primera vez. Necesitas tu CURP y un correo. | H8: Pendiente | K8: Persona solicitante | L8: Página (sitio/index.html)
A9: T008 | B9: Inicio | C9: Acreditación de poda y derribo, y de dictaminador técnico | D9: Texto | E9: Siempre | F9: Entra a tu cuenta Inicia o renueva tu acreditación y consulta en qué va tu trámite. | H9: Pendiente | K9: Persona solicitante | L9: Página (sitio/index.html)
A10: T009 | B10: Inicio | C10: Acreditación de poda y derribo, y de dictaminador técnico | D10: Texto | E10: Siempre | F10: Verifica una acreditación Consulta si una acreditación está vigente. No necesitas cuenta. | H10: Pendiente | K10: Persona solicitante | L10: Página (sitio/index.html)
A11: T010 | B11: Inicio | C11: Acreditación de poda y derribo, y de dictaminador técnico | D11: Texto | E11: Siempre | F11: Material de estudio Los documentos para preparar el examen. No necesitas cuenta. | H11: Pendiente | K11: Persona solicitante | L11: Página (sitio/index.html)
A12: T011 | B12: Inicio | C12: Cómo es el trámite | D12: Título | E12: Siempre | F12: Cómo es el trámite | H12: Pendiente | K12: Persona solicitante | L12: Página (sitio/index.html)
A13: T012 | B13: Inicio | C13: Cómo es el trámite | D13: Texto | E13: Siempre | F13: Creas tu cuenta con tu CURP y una fotografía de frente. Cada persona hace su propio trámite y necesita tener 18 años cumplidos el día de su solicitud. | H13: Pendiente | K13: Persona solicitante | L13: Página (sitio/index.html)
... A25: T024 | B25: Inicio | C25: Requisitos | D25: Texto | E25: Siempre | F25: Los documentos se cargan sólo en PDF, de hasta 5 MB cada uno. Al crear tu cuenta, además, cargas o tomas con tu teléfono una fotografía de frente (JPG o PNG). | H25: Pendiente | K25: Persona solicitante | L25: Página (sitio/index.html)
A26: T025 | B26: Inicio | C26: Requisitos | D26: Texto | E26: Siempre | F26: Cargando requisitos… | H26: Pendiente | J26: Texto momentáneo mientras cargan los datos. | K26: Persona solicitante | L26: Página (sitio/index.html)
A27: T026 | B27: Inicio | C27: Requisitos | D27: Título desplegable | E27: Uno por acreditación y modalidad | F27: «Poda y derribo» o «Dictaminador técnico» · «solicitud nueva» o «renovación» | H27: Pendiente | K27: Persona solicitante | L27: Código del sitio (sitio/app/inicio.js)
A28: T027 | B28: Inicio | C28: Requisitos | D28: Texto | E28: Requisito que se entrega en la cita | F28: Se entrega en la cita de cotejo. | H28: Pendiente | K28: Persona solicitante | L28: Código del sitio (sitio/app/inicio.js)
A29: T028 | B29: Inicio | C29: Requisitos | D29: Texto | E29: Requisito que se hace al entregar la credencial | F29: Se hace al recoger tu credencial. | H29: Pendiente | K29: Persona solicitante | L29: Código del sitio (sitio/app/inicio.js)
A30: T029 | B30: Inicio | C30: Requisitos | D30: Texto | E30: Bajo cada lista de requisitos | F30: Curso de N días; asistencia mínima de M días; calificación mínima del examen: X. Pago de derechos: $… (o «pendiente de la Gaceta Oficial»). | H30: Pendiente | K30: Persona solicitante | L30: Código del sitio (sitio/app/inicio.js)
A31: T030 | B31: Inicio | C31: Requisitos | D31: Error | E31: Si no se pudo cargar el catálogo | F31: No se pudieron cargar los requisitos. Intenta de nuevo más tarde. | H31: Pendiente | K31: Persona solicitante | L31: Código del sitio (sitio/app/inicio.js)
A32: T031 | B32: Crea tu cuenta | C32: — | D32: Botón o enlace | E32: Siempre | F32: Inicio | H32: Pendiente | K32: Persona solicitante | L32: Página (sitio/cuenta.html)
A33: T032 | B33: Crea tu cuenta | C33: — | D33: Aviso | E33: Siempre | F33: Ya entraste a tu cuenta Entraste como . Tu solicitud y su avance están en «Mis trámites». Ir a mis trámites ¿Vas a crear la cuenta de otra persona? Sal de esta cuenta y llena el formulario. | H33: Pendiente | K33: Persona solicitante | L33: Página (sitio/cuenta.html)
A34: T033 | B34: Crea tu cuenta | C34: — | D34: Texto | E34: Si hay un borrador guardado en el navegador | F34: Tienes una cuenta sin crear guardada en este dispositivo, con lo que habías escrito. La contraseña y la fotografía no se guardan: tendrás que ponerlas otra vez. | H34: Pendiente | K34: Persona solicitante | L34: Página (sitio/cuenta.html)
A35: T034 | B35: Crea tu cuenta | C35: — | D35: Botón o enlace | E35: Si hay un borrador guardado en el navegador | F35: Recuperar lo que escribiste | H35: Pendiente | K35: Persona solicitante | L35: Página (sitio/cuenta.html)
A36: T035 | B36: Crea tu cuenta | C36: — | D36: Botón o enlace | E36: Si hay un borrador guardado en el navegador | F36: Empezar de nuevo | H36: Pendiente | K36: Persona solicitante | L36: Página (sitio/cuenta.html)
A37: T036 | B37: Crea tu cuenta | C37: — | D37: Aviso | E37: Si hay un borrador guardado en el navegador | F37: ¿Descartar lo que escribiste? Se borra de este dispositivo y no se puede deshacer. ConservarDescartar | H37: Pendiente | K37: Persona solicitante | L37: Página (sitio/cuenta.html)
A38: T037 | B38: Crea tu cuenta | C38: Quién eres · ¿Quién eres? | D38: Título | E38: Siempre | F38: ¿Quién eres? | H38: Pendiente | K38: Persona solicitante | L38: Página (sitio/cuenta.html)
... A139: T138 | B139: Crea tu cuenta | C139: Aviso de privacidad simplificado | D139: Texto | E139: Al abrir la ventana «Aviso de privacidad simplificado» | F139: La Secretaría del Medio Ambiente recaba tu nombre, CURP (y de ella tu sexo), fotografía de frente, correo, teléfono y la institución para la que trabajas, si es el caso, para crear tu cuenta, tramitar tu acreditación, reconocerte en la cita, el curso y el examen, avisarte el avance y llevar el padrón de personas acreditadas. Al entregarte la credencial te toma otra fotografía, que es la que se imprime en ella. | H139: Pendiente | K139: Persona solicitante | L139: Página (sitio/cuenta.html)
A140: T139 | B140: Crea tu cuenta | C140: Aviso de privacidad simplificado | D140: Texto | E140: Al abrir la ventana «Aviso de privacidad simplificado» | F140: Fundamento: [Art. __, fracc. __]. Pendiente: lo completa la Unidad de Transparencia. | H140: Pendiente | J140: Lo completa la Unidad de Transparencia; no se inventa la cita. | K140: Persona solicitante | L140: Página (sitio/cuenta.html)
A141: T140 | B141: Crea tu cuenta | C141: Aviso de privacidad simplificado | D141: Botón o enlace | E141: Al abrir la ventana «Aviso de privacidad simplificado» | F141: Cerrar | H141: Pendiente | K141: Persona solicitante | L141: Página (sitio/cuenta.html)
A142: T141 | B142: Crea tu cuenta | C142: Al crear la cuenta | D142: Error | E142: Si ya hay una cuenta con esa CURP | F142: Ya hay una cuenta con esta CURP. Entra con ella; si no recuerdas tu contraseña, pide ayuda a la Secretaría. | H142: Pendiente | K142: Persona solicitante | L142: Código del sitio (sitio/app/config-cuenta.js)
A143: T142 | B143: Crea tu cuenta | C143: Al crear la cuenta | D143: Error | E143: CURP del registro de Kobo con otro nombre | F143: Tu nombre no coincide con el registro anterior de la Secretaría para esta CURP. Acude a la Secretaría para aclararlo. | H143: Pendiente | K143: Persona solicitante | L143: Código del sitio (sitio/app/config-cuenta.js)
A144: T143 | B144: Crea tu cuenta | C144: CURP | D144: Error | E144: Si la CURP no corresponde al nombre y apellidos | F144: La CURP no corresponde con el nombre y los apellidos que escribiste. Escríbelos tal como aparecen en tu CURP. | H144: Pendiente | K144: Persona solicitante | L144: Estándar de formularios (cruzada curp-nombre, sitio/formkit/js/validaciones.config.js)
A145: T144 | B145: Crea tu cuenta | C145: CURP | D145: Error | E145: Si la CURP indica segundo apellido y no se escribió | F145: Tu CURP indica que tienes segundo apellido. Escríbelo tal como aparece en tu CURP. | H145: Pendiente | K145: Persona solicitante | L145: Estándar de formularios (cruzada curp-segundo-apellido, sitio/formkit/js/validaciones.config.js)
A146: T145 | B146: Entrar | C146: — | D146: Botón o enlace | E146: Siempre | F146: Inicio | H146: Pendiente | K146: Persona solicitante | L146: Página (sitio/entrar.html)
A147: T146 | B147: Entrar | C147: Entra a tu cuenta | D147: Título | E147: Siempre | F147: Entra a tu cuenta | H147: Pendiente | K147: Persona solicitante | L147: Página (sitio/entrar.html)
A148: T147 | B148: Entrar | C148: Entra a tu cuenta | D148: Nota | E148: Siempre | F148: Las preguntas con * son obligatorias. | H148: Pendiente | K148: Persona solicitante | L148: Página (sitio/entrar.html)
A149: T148 | B149: Entrar | C149: Entra a tu cuenta | D149: Pregunta | E149: Siempre | F149: CURP | H149: Pendiente | K149: Persona solicitante | L149: Página (sitio/entrar.html)
A150: T149 | B150: Entrar | C150: Entra a tu cuenta | D150: Pregunta | E150: Siempre | F150: Contraseña | H150: Pendiente | K150: Persona solicitante | L150: Página (sitio/entrar.html)
A151: T150 | B151: Entrar | C151: Entra a tu cuenta | D151: Botón o enlace | E151: Siempre | F151: Entrar | H151: Pendiente | K151: Persona solicitante | L151: Página (sitio/entrar.html)
...
